2025-04-30 00:26:23,080 INFO    MainThread:14560 [wandb_init.py:setup_run_log_directory():724] Logging user logs to C:\Users\oplab\Desktop\Tony\Thyroid\code\wandb\run-20250430_002623-11vb8mxn\logs\debug.log
2025-04-30 00:26:23,080 INFO    MainThread:14560 [wandb_init.py:setup_run_log_directory():725] Logging internal logs to C:\Users\oplab\Desktop\Tony\Thyroid\code\wandb\run-20250430_002623-11vb8mxn\logs\debug-internal.log
2025-04-30 00:26:23,080 INFO    MainThread:14560 [wandb_init.py:init():852] calling init triggers
2025-04-30 00:26:23,080 INFO    MainThread:14560 [wandb_init.py:init():857] wandb.init called with sweep_config: {}
config: {'image_size': 128, 'learning_rate': 0.001, 'epochs': 20, 'batch_size': 8, '_wandb': {}}
2025-04-30 00:26:24,365 INFO    MainThread:14560 [wandb_init.py:init():893] starting backend
2025-04-30 00:26:24,365 INFO    MainThread:14560 [wandb_init.py:init():897] sending inform_init request
2025-04-30 00:26:24,366 INFO    MainThread:14560 [backend.py:_multiprocessing_setup():101] multiprocessing start_methods=spawn, using: spawn
2025-04-30 00:26:24,367 INFO    MainThread:14560 [wandb_init.py:init():907] backend started and connected
2025-04-30 00:26:24,370 INFO    MainThread:14560 [wandb_run.py:_label_probe_notebook():1369] probe notebook
2025-04-30 00:26:24,370 INFO    MainThread:14560 [wandb_run.py:_label_probe_notebook():1379] Unable to probe notebook: 'NoneType' object has no attribute 'get'
2025-04-30 00:26:24,370 INFO    MainThread:14560 [wandb_init.py:init():1002] updated telemetry
2025-04-30 00:26:24,404 INFO    MainThread:14560 [wandb_init.py:init():1026] communicating run to backend with 90.0 second timeout
2025-04-30 00:26:24,958 INFO    MainThread:14560 [wandb_init.py:init():1101] starting run threads in backend
2025-04-30 00:26:25,154 INFO    MainThread:14560 [wandb_run.py:_console_start():2566] atexit reg
2025-04-30 00:26:25,155 INFO    MainThread:14560 [wandb_run.py:_redirect():2414] redirect: wrap_raw
2025-04-30 00:26:25,155 INFO    MainThread:14560 [wandb_run.py:_redirect():2483] Wrapping output streams.
2025-04-30 00:26:25,155 INFO    MainThread:14560 [wandb_run.py:_redirect():2506] Redirects installed.
2025-04-30 00:26:25,156 INFO    MainThread:14560 [wandb_init.py:init():1147] run started, returning control to user process
2025-04-30 00:26:42,571 WARNING MsgRouterThr:14560 [router.py:message_loop():63] [no run ID] message_loop has been closed
Traceback (most recent call last):
  File "C:\Users\oplab\anaconda3\envs\thyroid\Lib\site-packages\wandb\sdk\lib\sock_client.py", line 208, in _read_packet_bytes
    data = self._sock.recv(self._bufsize)
           ^^^^^^^^^^^^^^^^^^^^^^^^^^^^^^
ConnectionResetError: [WinError 10054] 遠端主機已強制關閉一個現存的連線。

The above exception was the direct cause of the following exception:

Traceback (most recent call last):
  File "C:\Users\oplab\anaconda3\envs\thyroid\Lib\site-packages\wandb\sdk\interface\router_sock.py", line 27, in _read_message
    return self._sock_client.read_server_response(timeout=1)
           ^^^^^^^^^^^^^^^^^^^^^^^^^^^^^^^^^^^^^^^^^^^^^^^^^
  File "C:\Users\oplab\anaconda3\envs\thyroid\Lib\site-packages\wandb\sdk\lib\sock_client.py", line 235, in read_server_response
    data = self._read_packet_bytes(timeout=timeout)
           ^^^^^^^^^^^^^^^^^^^^^^^^^^^^^^^^^^^^^^^^
  File "C:\Users\oplab\anaconda3\envs\thyroid\Lib\site-packages\wandb\sdk\lib\sock_client.py", line 212, in _read_packet_bytes
    raise SockClientClosedError from e
wandb.sdk.lib.sock_client.SockClientClosedError

The above exception was the direct cause of the following exception:

Traceback (most recent call last):
  File "C:\Users\oplab\anaconda3\envs\thyroid\Lib\site-packages\wandb\sdk\interface\router.py", line 56, in message_loop
    msg = self._read_message()
          ^^^^^^^^^^^^^^^^^^^^
  File "C:\Users\oplab\anaconda3\envs\thyroid\Lib\site-packages\wandb\sdk\interface\router_sock.py", line 29, in _read_message
    raise MessageRouterClosedError from e
wandb.sdk.interface.router.MessageRouterClosedError
2025-04-30 00:26:42,579 INFO    MsgRouterThr:14560 [mailbox.py:close():129] [no run ID] Closing mailbox, abandoning 2 handles.
